Workbook

Sheet Dashboard
A1: DASHBOARD DATA
A3: Total Hasil Cutting | C3: Total Pesanan Offline Sudah Bayar | E3: Total Hasil Jahit/SKU | H3: Total Pengeluaran Barang Offline/SKU
A4: =SUM(Hasil_Cutting!C:C) | C4: =COUNTIF(Pengeluaran_Barang_Offline!G:G,TRUE) | E4: SKU | F4: JUMLAH | H4: SKU | I4: JUMLAH
A6: Total Kredit | C6: Total Pesanan Offline Belum Bayar
A7: =SUM(Modal_Hutang!G:G) | C7: =COUNTIF(Pengeluaran_Barang_Offline!G:G,FALSE)
A9: Total Deposit | C9: Total Saldo Operasional
A10: =SUM(Modal_Hutang!#REF!)
A12: Total Pengeluaran Modal Operasional

Sheet Hasil_Cutting
A1: Tanggal | B1: SKU | C1: Jumlah
A2: 2026-04-14 | B2: JSO-Smoke | C2: 116
A3: 2026-04-14 | B3: JSO-Almond | C3: 20
A4: 2026-04-14 | B4: JSO-Grey | C4: 116
A5: 2026-04-14 | B5: JSO-Cokelat Tua | C5: 146
A6: 2026-04-14 | B6: JSO-Softpink | C6: 120
A7: 2026-04-14 | B7: JSO-Hitam | C7: 174
A8: 2026-04-14 | B8: DG-Almond | C8: 88
A9: 2026-04-14 | B9: DG-Grey | C9: 100

Sheet Distribusi_Cutting
A1: Tanggal | B1: Jenis | C1: Nama | D1: SKU | E1: Jumlah
A2: 2026-04-14 | B2: Peng-Sup | C2: Kak Tarul | D2: DG-Almond | E2: 88
A3: 2026-04-14 | B3: Peng-Sup | C3: Kak Tarul | D3: DG-Grey | E3: 100
A4: 2026-04-14 | B4: Peng-Sup | C4: Kak Tarul | D4: JSO-Cokelat Tua | E4: 146

Sheet Modal_Hutang
A1: Tanggal | B1: Nama | C1: Jenis | D1: Jumlah | E1: Harga Satuan | F1: Total | G1: Kredit | J1: Tanggal | K1: Nama | L1: Jenis | M1: Jumlah | N1: Harga Satuan | O1: Total | P1: Deposit
A2: 2026-04-13 | B2: Kak Boden | C2: Label Akrilik | D2: 20000 | E2: 250 | F2: =D2*E2 | G2: 5000000 | J2: 2026-04-13 | M2: 0 | N2: 0 | O2: =M2*N2 | P2: 0
A3: 2026-04-14 | B3: Kak Yudi | C3: Kain Jersey | D3: 635.04 | E3: 58000 | F3: =D3*E3 | G3: 36832320 | J3: 2026-04-14 | K3: Kak Yudi | L3: Kain Jersey | M3: 635.04 | N3: 58000 | O3: =M3*N3 | P3: 36832320
A4: 2026-04-14 | B4: Kak Yudi | C4: Kain Jersey | D4: 433.74 | E4: 60000 | F4: =D4*E4 | G4: 26024400 | J4: 2026-04-20 | K4: Kak Yudi | L4: Kain Jersey | M4: 433.74 | N4: 60000 | O4: =M4*N4 | P4: 26024400
A5: 2026-04-14 | B5: Kak Yudi | C5: Kain Jersey | D5: 457.94 | E5: 60000 | F5: =D5*E5 | G5: 27476400 | J5: 2026-04-20 | K5: Kak Yudi | L5: Kain Jersey | M5: 457.94 | N5: 60000 | O5: =M5*N5 | P5: 27476400
A6: 2026-04-14 | B6: Kak Yudi | C6: Kain Jersey | D6: 479.65 | E6: 60000 | F6: =D6*E6 | G6: 28779000 | J6: 46135 | K6: Kak Yudi | L6: Kain Jersey | M6: 479.65 | N6: 60000 | O6: =M6*N6 | P6: 28779000
A7: 2026-04-14 | B7: Kak Yudi | C7: Kain Jersey | D7: 304.31 | E7: 60000 | F7: =D7*E7 | G7: 18258600 | J7: 46135 | K7: Kak Yudi | L7: Kain Jersey | M7: 304.31 | N7: 60000 | O7: =M7*N7 | P7: 18258600
A8: 2026-04-14 | B8: Kak Kemat | C8: Label Akrilik | D8: 15000 | E8: 250 | F8: =D8*E8 | G8: 3750000 | J8: 2026-04-14 | K8: Kak Kemat | L8: Label Akrilik | M8: 15000 | N8: 250 | O8: =M8*N8 | P8: 3750000
A9: 2026-04-15 | B9: Kak Yudi | C9: Kain Jersey | D9: =25.3+25.95+26.07+25.55+25.1+25.96+24.55+25.65+25.2+26.9 | E9: 60000 | F9: =D9*E9 | G9: 15373800 | J9: 2026-04-15 | K9: Kak Yudi | L9: Kain Jersey | M9: =25.3+25.95+26.07+25.55+25.1+25.96+24.55+25.65+25.2+26.9 | N9: 60000 | O9: =M9*N9 | P9: 15373800
A10: 2026-04-16 | B10: Kak Yudi | C10: Kain Jersey | D10: 76.4 | E10: 60000 | F10: =D10*E10 | G10: 4584000 | J10: 2026-04-16 | K10: Kak Yudi | L10: Kain Jersey | M10: 76.4 | N10: 60000 | O10: =M10*N10 | P10: 4584000
A11: 2026-04-17 | B11: Kak Yudi | C11: Kain Jersey | D11: 202.7 | E11: 60000 | F11: =D11*E11 | G11: 12162000 | J11: 2026-04-17 | K11: Kak Yudi | L11: Kain Jersey | M11: 202.7 | N11: 60000 | O11: =M11*N11 | P11: 12162000
A12: 2026-04-18 | B12: Kak Yudi | C12: Kain Jersey | D12: =76.05+50.3+125.87 | E12: 60000 | F12: =D12*E12 | G12: 15133200 | J12: 2026-04-18 | K12: Kak Yudi | L12: Kain Jersey | M12: =76.05+50.3+125.87 | N12: 60000 | O12: =M12*N12 | P12: 15133200
A13: 2026-04-20 | B13: Kak Yudi | C13: Kain Jersey | D13: 407.27 | E13: 60000 | F13: =D13*E13 | G13: 24436200 | J13: 2026-04-20 | K13: Kak Yudi | L13: Kain Jersey | M13: 407.27 | N13: 60000 | O13: =M13*N13 | P13: 24436200
A14: 2026-04-22 | B14: Kak Yudi | C14: Kain Jersey | D14: 229.37 | E14: 60000 | F14: =D14*E14 | G14: 13762200 | J14: 2026-04-22 | K14: Kak Yudi | L14: Kain Jersey | M14: 229.37 | N14: 60000 | O14: =M14*N14 | P14: 13762200
A15: 2026-04-22 | B15: Salim Cap | C15: Hangtag | D15: 25000 | E15: 215 | F15: =D15*E15 | G15: 5375000 | J15: 2026-04-22 | K15: Salim Cap | L15: Hangtag | M15: 25000 | N15: 215 | O15: =M15*N15 | P15: 5375000
A16: 2026-04-23 | B16: Kak Yudi | C16: Kain Jersey | D16: 229.41 | E16: 60000 | F16: =D16*E16 | G16: 13764600 | J16: 2026-05-11 | K16: Kak Yudi | L16: Kain Jersey | M16: 229.41 | N16: 60000 | P16: 13764600
A17: 2026-04-25 | B17: Kak Yudi | C17: Kain Jersey | D17: 329.23 | E17: 60000 | F17: =D17*E17 | G17: 19753800 | J17: 2026-05-11 | K17: Kak Yudi | L17: Kain Jersey | M17: 329.23 | N17: 60000 | P17: 19753800
A18: 2026-04-27 | B18: Kak Boden | C18: Cap Wooven | D18: 120000 | E18: 150 | F18: =D18*E18 | G18: 18000000 | J18: 2026-05-08 | K18: Kak Boden | L18: Cap Wooven | M18: 120000 | N18: 150 | P18: 10000000
A19: 2026-04-27 | B19: Kak Yudi | C19: Kain Jersey | D19: 251.91 | E19: 60000 | F19: =D19*E19 | G19: 15114600 | J19: - | K19: - | L19: - | M19: 0 | N19: 0 | P19: 0
A20: 2026-04-28 | B20: Kak Yudi | C20: Kain Jersey | D20: 179.12 | E20: 60000 | F20: =D20*E20 | G20: 10747200 | J20: - | K20: - | L20: - | M20: 0 | N20: 0 | P20: 0
A21: 2026-04-29 | B21: Kak Yudi | C21: Kain Jersey | D21: 127.58 | E21: 60000 | F21: =D21*E21 | G21: 7654800 | J21: - | K21: - | L21: - | M21: 0 | N21: 0 | P21: 0
A22: 2026-04-30 | B22: Kak Yudi | C22: Kain Jersey | D22: 229.6 | E22: 60000 | F22: =D22*E22 | G22: 13776000 | J22: - | K22: - | L22: - | M22: 0 | N22: 0 | P22: 0
A23: 2026-05-02 | B23: Kak Yudi | C23: Kain Jersey | D23: 101.65 | E23: 60000 | F23: =D23*E23 | G23: 6099000 | J23: - | K23: - | L23: - | M23: 0 | N23: 0 | P23: 0
A24: 2026-05-01 | B24: Kak Yudi | C24: Kain Jersey | D24: 152.33 | E24: 60000 | F24: =D24*E24 | G24: 9139800 | J24: - | K24: - | L24: - | M24: 0 | N24: 0 | P24: 0
A25: 2026-05-04 | B25: Kak Yudi | C25: Kain Jersey | D25: 278.79 | E25: 60000 | F25: =D25*E25 | G25: 16727400 | J25: - | K25: - | L25: - | M25: 0 | N25: 0 | P25: 0
A26: 2026-05-05 | B26: Kak Yudi | C26: Kain Jersey | D26: 100.96 | E26: 60000 | F26: =D26*E26 | G26: 6057600 | J26: - | K26: - | L26: - | M26: 0 | N26: 0 | P26: 0
A27: 2026-05-06 | B27: Kak Yudi | C27: Kain Jersey | D27: 406.63 | E27: 60000 | F27: =D27*E27 | G27: 24397800 | J27: - | K27: - | L27: - | M27: 0 | N27: 0 | P27: 0
A28: 2026-05-07 | B28: Kak Yudi | C28: Kain Jersey | D28: 100.5 | E28: 60000 | F28: =D28*E28 | G28: 6030000 | J28: - | K28: - | L28: - | M28: 0 | N28: 0 | P28: 0
A29: 2026-05-08 | B29: Kak Yudi | C29: Kain Jersey | D29: 75.95 | E29: 60000 | F29: =D29*E29 | G29: 4557000 | P29: 0
A30: 2026-05-09 | B30: Kak Yudi | C30: Kain Jersey | D30: 280.1 | E30: 60000 | F30: =D30*E30 | G30: 16806000 | P30: 0

Sheet Modal_Operasional
A1: Tanggal | B1: Jenis | C1: Nama | D1: Jumlah | E1: Harga Satuan | F1: Total
A2: 2026-04-14 | B2: Overhead | C2: Uang Makan | D2: 1 | E2: 50000 | F2: =D2*E2
A3: 2026-04-22 | B3: Barang | C3: Zaini | D3: 1 | E3: 275500 | F3: =D3*E3
A4: 2026-04-22 | B4: Barang | C4: Tali Hangtak | D4: 20000 | E4: 32 | F4: =D4*E4
A5: 2026-04-22 | B5: Utilitas | C5: Litrik | D5: 1 | E5: 524046 | F5: =D5*E5
A6: 2026-04-15 | B6: Utilitas | C6: Wifi Indihome | D6: 1 | E6: 363760 | F6: =D6*E6
A7: 2026-04-23 | B7: Barang | C7: Label Wooven | D7: 10000 | E7: 150 | F7: =D7*E7
A8: 2026-04-23 | B8: Overhead | C8: Uang Makan | D8: 1 | E8: 50000 | F8: =D8*E8
A9: 2026-04-24 | B9: Barang | C9: Baterai Alkaline 2+1 | D9: 1 | E9: 22500 | F9: =D9*E9
A10: 2026-04-24 | B10: Barang | C10: Benang Jahit | D10: 1 | E10: 26000 | F10: =D10*E10
A11: 2026-04-24 | B11: Barang | C11: Tali Goni | D11: 1 | E11: 100000 | F11: =D11*E11
A12: 2026-04-25 | B12: Barang | C12: Plastik 15 | D12: 4 | E12: 75000 | F12: =D12*E12
A13: 2026-04-25 | B13: Overhead | C13: Harian (pasukan) | D13: 1 | E13: 2441620 | F13: =D13*E13
... A41: 2026-05-08 | B41: Barang | C41: Tinta Printer Hitam | D41: 1 | E41: 100000 | F41: =D41*E41

Sheet Pengeluaran_Barang_Offline
A1: Tanggal | B1: Nama | C1: SKU | D1: Jumlah | E1: Harga Satuan | F1: Total | G1: Sudah Bayar
A2: 2026-04-20 | B2: Kak Imam | C2: DG-M | D2: 76 | E2: =VLOOKUP(C2, SKU_Induk!$A$2:$B$1000, 2, FALSE) | F2: =D2*E2 | G2: 0
A3: 2026-04-20 | B3: Kak Imam | C3: JSO | D3: 6 | E3: =VLOOKUP(C3, SKU_Induk!$A$2:$B$1000, 2, FALSE) | F3: =D3*E3 | G3: 0
A4: 2026-04-20 | B4: Kak Imam | C4: SA-L | D4: 8 | E4: =VLOOKUP(C4, SKU_Induk!$A$2:$B$1000, 2, FALSE) | F4: =D4*E4 | G4: 0
A5: 2026-04-21 | B5: Kak Imam | C5: DG-M | D5: 80 | E5: =VLOOKUP(C5, SKU_Induk!$A$2:$B$1000, 2, FALSE) | F5: =D5*E5 | G5: 0
A6: 2026-04-22 | B6: Kak Imam | C6: DG-M | D6: 55 | E6: =VLOOKUP(C6, SKU_Induk!$A$2:$B$1000, 2, FALSE) | F6: =D6*E6 | G6: 0
A7: 2026-04-22 | B7: Kak Imam | C7: SA-L | D7: 2 | E7: =VLOOKUP(C7, SKU_Induk!$A$2:$B$1000, 2, FALSE) | F7: =D7*E7 | G7: 0
A8: 2026-04-25 | B8: Kak Yudi | C8: JSO | D8: 8 | E8: =VLOOKUP(C8, SKU_Induk!$A$2:$B$1000, 2, FALSE) | F8: =D8*E8 | G8: 104000
A9: 2026-04-27 | B9: Kak Imam | C9: DG-M | D9: 10 | E9: =VLOOKUP(C9, SKU_Induk!$A$2:$B$1000, 2, FALSE) | F9: =D9*E9 | G9: 99000
A10: 2026-04-27 | B10: Kak Imam | C10: JSO | D10: 3 | E10: =VLOOKUP(C10, SKU_Induk!$A$2:$B$1000, 2, FALSE) | F10: =D10*E10 | G10: 78000
A11: 2026-04-25 | B11: Kak Imam | C11: DG-M | D11: 37 | E11: =VLOOKUP(C11, SKU_Induk!$A$2:$B$1000, 2, FALSE) | F11: =D11*E11 | G11: 286000
A12: 2026-04-22 | B12: Kak Imam | C12: Kertas Resi | D12: 1 | E12: =VLOOKUP(C12, SKU_Induk!$A$2:$B$1000, 2, FALSE) | F12: =D12*E12 | G12: 165000
A13: 2026-04-27 | B13: Kak Yudi | C13: Kertas Resi | D13: 3 | E13: =VLOOKUP(C13, SKU_Induk!$A$2:$B$1000, 2, FALSE) | F13: =D13*E13 | G13: 99000
A14: 2026-04-29 | B14: Kak Yudi | C14: JSO | D14: 6 | E14: =VLOOKUP(C14, SKU_Induk!$A$2:$B$1000, 2, FALSE) | F14: =D14*E14 | G14: 78000
A15: 2026-04-30 | B15: Kak Imam | C15: DG-M | D15: 30 | E15: =VLOOKUP(C15, SKU_Induk!$A$2:$B$1000, 2, FALSE) | F15: 0 | G15: 0
A16: 2026-04-30 | B16: Kak Imam | C16: JSO | D16: 3 | E16: =VLOOKUP(C16, SKU_Induk!$A$2:$B$1000, 2, FALSE) | F16: 0 | G16: 0
A17: 2026-05-04 | B17: Kaji Yudi | C17: DG-M | D17: 50 | E17: =VLOOKUP(C17, SKU_Induk!$A$2:$B$1000, 2, FALSE) | F17: 0 | G17: 0
A18: 2026-05-04 | B18: Kak Imam | C18: DG-M | D18: 63 | E18: =VLOOKUP(C18, SKU_Induk!$A$2:$B$1000, 2, FALSE) | F18: 0 | G18: 0
A19: 2026-05-04 | B19: Kak Imam | C19: JSO | D19: 2 | E19: =VLOOKUP(C19, SKU_Induk!$A$2:$B$1000, 2, FALSE) | F19: 0 | G19: 0
A20: 2026-05-04 | B20: Kak Imam | C20: DG-M | D20: 53 | E20: =VLOOKUP(C20, SKU_Induk!$A$2:$B$1000, 2, FALSE) | F20: 0 | G20: 0
A21: 2026-05-05 | B21: Kak Imam | C21: DG-M | D21: 110 | E21: =VLOOKUP(C21, SKU_Induk!$A$2:$B$1000, 2, FALSE) | F21: 0 | G21: 0
A22: 2026-05-05 | B22: Kak Imam | C22: JSO | D22: 13 | E22: =VLOOKUP(C22, SKU_Induk!$A$2:$B$1000, 2, FALSE) | F22: 0 | G22: 0
A23: 2026-05-05 | B23: Kak Imam | C23: Plastik Packing Hitam | D23: 2 | E23: =VLOOKUP(C23, SKU_Induk!$A$2:$B$1000, 2, FALSE) | F23: 0 | G23: 0
A24: 2026-05-06 | B24: Kak Imam | C24: DG-M | D24: 34 | E24: =VLOOKUP(C24, SKU_Induk!$A$2:$B$1000, 2, FALSE) | F24: 0 | G24: 0
A25: 2026-05-06 | B25: Kak Imam | C25: JSO | D25: 2 | E25: =VLOOKUP(C25, SKU_Induk!$A$2:$B$1000, 2, FALSE) | F25: 0 | G25: 0
A26: 2026-05-06 | B26: Kak Imam | C26: S3 | D26: 1 | E26: =VLOOKUP(C26, SKU_Induk!$A$2:$B$1000, 2, FALSE) | F26: 0 | G26: 0
A27: 2026-05-07 | B27: Kak Yudi | C27: JSO | D27: 22 | E27: 13000 | F27: 286000 | G27: 286000
A28: 2026-05-07 | B28: Kak Yudi | C28: Kertas Resi | D28: 5 | E28: 33000 | F28: 165000 | G28: 165000
A29: 2026-05-07 | B29: Kak Imam | C29: DG-M | D29: 20 | E29: 10000 | F29: 200000 | G29: 0
A30: 2026-05-07 | B30: Kak Imam | C30: SA-L | D30: 6 | E30: 8000 | F30: 48000 | G30: 0
A31: 2026-05-07 | B31: Kak Imam | C31: JSO | D31: 8 | E31: 13000 | F31: 104000 | G31: 0
A32: 2026-05-08 | B32: Kak Imam | C32: DG-M | D32: 50 | E32: 10000 | F32: 500000 | G32: 0
A33: 2026-05-08 | B33: Kak Imam | C33: JSO | D33: 2 | E33: 13000 | F33: 26000 | G33: 0
A34: 2026-05-08 | B34: Kak Imam | C34: SA-L | D34: 1 | E34: 8000 | F34: 8000 | G34: 0
A35: 2026-05-08 | B35: Kak Imam | C35: S3 | D35: 2 | E35: 10000 | F35: 20000 | G35: 0

Sheet Barang_Terhutang
A1: Tgl Ambil | B1: Nama | C1: SKU | D1: Qty | E1: Harga | F1: Formula | G1: Total | J1: Tgl Lunas | K1: Nama | L1: SKU | M1: Qty | N1: Harga | O1: Formula | P1: Total Lunas
A2: 2026-04-21 | B2: Kak Yudi | C2: DG-Bata | D2: 4 | E2: 9000 | F2: =D2*E2 | G2: 36000 | J2: 2026-04-23 | K2: Kak Yudi | L2: DG-Bata | M2: 4 | N2: 9000 | O2: 36000 | P2: 36000
A3: 2026-04-21 | B3: Kak Yudi | C3: DG-Denim | D3: 2 | E3: 9000 | F3: =D3*E3 | G3: 18000 | J3: 2026-04-23 | K3: Kak Yudi | L3: DG-Denim | M3: 2 | N3: 9000 | O3: 18000 | P3: 18000
A4: 2026-04-21 | B4: Kak Yudi | C4: DG-Navy | D4: 4 | E4: 9000 | F4: =D4*E4 | G4: 36000 | J4: 2026-04-23 | K4: Kak Yudi | L4: DG-Navy | M4: 4 | N4: 9000 | O4: 36000 | P4: 36000
A5: 2026-04-21 | B5: Kak Yudi | C5: DG-Turkish-L | D5: 4 | E5: 10500 | F5: =D5*E5 | G5: 42000 | J5: 2026-04-23 | K5: Kak Yudi | L5: DG-Turkish-L | M5: 4 | N5: 10500 | O5: 42000 | P5: 42000
A6: 2026-04-21 | B6: Kak Yudi | C6: SA-Dark grey-L | D6: 1 | E6: 7500 | F6: =D6*E6 | G6: 7500 | J6: 2026-04-23 | K6: Kak Yudi | L6: SA-Dark grey-L | M6: 1 | N6: 7500 | O6: 7500 | P6: 7500
A7: 2026-04-21 | B7: Kak Yudi | C7: SA-Navy-L | D7: 1 | E7: 7500 | F7: =D7*E7 | G7: 7500 | J7: 2026-04-23 | K7: Kak Yudi | L7: SA-Navy-L | M7: 1 | N7: 7500 | O7: 7500 | P7: 7500
A8: 2026-04-21 | B8: Kak Yudi | C8: SA-Jotol-L | D8: 1 | E8: 7500 | F8: =D8*E8 | G8: 7500 | J8: 2026-04-23 | K8: Kak Yudi | L8: SA-Jotol-L | M8: 1 | N8: 7500 | O8: 7500 | P8: 7500
A9: 2026-04-21 | B9: Kak Yudi | C9: SPORT-Jotol-S | D9: 1 | E9: 5000 | F9: =D9*E9 | G9: 5000 | J9: 2026-04-23 | K9: Kak Yudi | L9: SPORT-Jotol-S | M9: 1 | N9: 5000 | O9: 5000 | P9: 5000
A10: 2026-04-21 | B10: Kak Yudi | C10: SPORT-Army-S | D10: 1 | E10: 5000 | F10: =D10*E10 | G10: 5000 | J10: 2026-04-23 | K10: Kak Yudi | L10: SPORT-Army-S | M10: 1 | N10: 5000 | O10: 5000 | P10: 5000
A11: 2026-04-21 | B11: Kak Yudi | C11: SPORT-Marun-S | D11: 1 | E11: 5000 | F11: =D11*E11 | G11: 5000 | J11: 2026-04-23 | K11: Kak Yudi | L11: SPORT-Marun-S | M11: 1 | N11: 5000 | O11: 5000 | P11: 5000
A12: 2026-04-21 | B12: Kak Yudi | C12: SPORT-Navy-S | D12: 1 | E12: 5000 | F12: =D12*E12 | G12: 5000 | J12: 2026-04-23 | K12: Kak Yudi | L12: SPORT-Navy-S | M12: 1 | N12: 5000 | O12: 5000 | P12: 5000
A13: 2026-04-21 | B13: Kak Yudi | C13: SPORT-Navy-L | D13: 1 | E13: 9500 | F13: =D13*E13 | G13: 9500 | J13: 2026-04-23 | K13: Kak Yudi | L13: SPORT-Navy-L | M13: 1 | N13: 9500 | O13: 9500 | P13: 9500
... A18: 2026-04-21 | B18: Kak Yudi | C18: JSO-Hitam | D18: 456 | E18: 11500 | F18: =D18*E18 | G18: 5244000 | J18: 2026-04-23 | K18: Kak Yudi | L18: JSO-Hitam | M18: 456 | N18: 11500 | O18: 5244000 | P18: 5244000
A19: 2026-04-19 | B19: Kak Hari | C19: JSO-Maroon | D19: 155 | E19: 11500 | F19: =D19*E19 | G19: 1782500 | J19: 46135 | K19: Kak Hari | L19: JSO-Maroon | M19: 155 | N19: 11500 | O19: =M19*N19 | P19: 1782500
A20: 2026-04-19 | B20: Kak Hari | C20: JSO-Navy | D20: 176 | E20: 11500 | F20: =D20*E20 | G20: 2024000 | J20: 46135 | K20: Kak Hari | L20: JSO-Navy | M20: 176 | N20: 11500 | O20: =M20*N20 | P20: 2024000
A21: 2026-04-19 | B21: Kak Hari | C21: JSO-Maroon | D21: 181 | E21: 11500 | F21: =D21*E21 | G21: 2081500 | J21: 46135 | K21: Kak Hari | L21: JSO-Maroon | M21: 181 | N21: 11500 | O21: =M21*N21 | P21: 2081500
A22: 2026-04-19 | B22: Kak Hari | C22: JSO-Navy | D22: 174 | E22: 11500 | F22: =D22*E22 | G22: 2001000 | J22: 46135 | K22: Kak Hari | L22: JSO-Navy | M22: 174 | N22: 11500 | O22: =M22*N22 | P22: 2001000
A23: 2026-04-19 | B23: Kak Hari | C23: JSO-Burgundy | D23: 168 | E23: 11500 | F23: =D23*E23 | G23: 1932000 | J23: 46135 | K23: Kak Hari | L23: JSO-Burgundy | M23: 168 | N23: 11500 | O23: =M23*N23 | P23: 1932000
A24: 2026-04-19 | B24: Kak Hari | C24: JSO-Cream | D24: 341 | E24: 11500 | F24: =D24*E24 | G24: 3921500 | J24: 2026-04-23 | K24: Kak Hari | L24: JSO-Cream | M24: 341 | N24: 11500 | O24: =M24*N24 | P24: 3921500
A25: 2026-04-19 | B25: Kak Hari | C25: DG-Hitam | D25: 218 | E25: 9000 | F25: =D25*E25 | G25: 1962000 | J25: 46135 | K25: Kak Hari | L25: DG-Hitam | M25: 218 | N25: 9000 | O25: =M25*N25 | P25: 1962000
A26: 2026-04-19 | B26: Kak Hari | C26: DG-Hitam | D26: 432 | E26: 9000 | F26: =D26*E26 | G26: 3888000 | J26: 46135 | K26: Kak Hari | L26: DG-Hitam | M26: 432 | N26: 9000 | O26: =M26*N26 | P26: 3888000
A27: 2026-04-22 | B27: Kak Yudi | C27: SPORT-Hazelnut-L | D27: 2 | E27: 9500 | F27: =D27*E27 | G27: 19000 | J27: 2026-04-23 | K27: Kak Yudi | L27: SPORT-Hazelnut-L | M27: 2 | N27: 9500 | O27: =M27*N27 | P27: 19000
A28: 2026-04-22 | B28: Kak Yudi | C28: SPORT-Navy-L | D28: 1 | E28: 9500 | F28: =D28*E28 | G28: 9500 | J28: 2026-04-23 | K28: Kak Yudi | L28: SPORT-Navy-L | M28: 1 | N28: 9500 | O28: =M28*N28 | P28: 9500
A29: 2026-04-22 | B29: Kak Yudi | C29: SPORT-Mustard-M | D29: 1 | E29: 7500 | F29: =D29*E29 | G29: 7500 | J29: 2026-04-23 | K29: Kak Yudi | L29: SPORT-Mustard-M | M29: 1 | N29: 7500 | O29: =M29*N29 | P29: 7500
A30: 2026-04-22 | B30: Kak Yudi | C30: SPORT-Smoke-S | D30: 1 | E30: 5000 | F30: =D30*E30 | G30: 5000 | J30: 2026-04-23 | K30: Kak Yudi | L30: SPORT-Smoke-S | M30: 1 | N30: 5000 | O30: =M30*N30 | P30: 5000
A31: 2026-04-22 | B31: Kak Yudi | C31: SPORT-Jotol-S | D31: 1 | E31: 5000 | F31: =D31*E31 | G31: 5000 | J31: 2026-04-23 | K31: Kak Yudi | L31: SPORT-Jotol-S | M31: 1 | N31: 5000 | O31: =M31*N31 | P31: 5000
A32: 2026-04-22 | B32: Kak Yudi | C32: P-Polos-Maroon | D32: 1 | E32: 11500 | F32: =D32*E32 | G32: 11500 | J32: 2026-04-23 | K32: Kak Yudi | L32: P-Polos-Maroon | M32: 1 | N32: 11500 | O32: =M32*N32 | P32: 11500
A33: 2026-04-22 | B33: Kak Yudi | C33: DG-Maroon | D33: 2 | E33: 9000 | F33: =D33*E33 | G33: 18000 | J33: 2026-04-23 | K33: Kak Yudi | L33: DG-Maroon | M33: 2 | N33: 9000 | O33: =M33*N33 | P33: 18000
A34: 2026-04-22 | B34: Kak Yudi | C34: DG-Denim | D34: 4 | E34: 9000 | F34: =D34*E34 | G34: 36000 | J34: 2026-04-23 | K34: Kak Yudi | L34: DG-Denim | M34: 4 | N34: 9000 | O34: =M34*N34 | P34: 36000
A35: 2026-04-23 | B35: Kaji Yudi | C35: JSO-Hitam | D35: 903 | E35: 11500 | F35: =D35*E35 | G35: 10384500 | J35: 2026-04-23 | K35: Kaji Yudi | L35: JSO-Hitam | M35: 903 | N35: 11500 | O35: =M35*N35 | P35: 10384500
A36: 2026-04-23 | B36: Kaji Yudi | C36: JSO-Choco | D36: 80 | E36: 11500 | F36: =D36*E36 | G36: 920000 | J36: 2026-04-23 | K36: Kaji Yudi | L36: JSO-Choco | M36: 80 | N36: 11500 | O36: =M36*N36 | P36: 920000
A37: 2026-04-23 | B37: Kaji Yudi | C37: JSO-Fossil | D37: 150 | E37: 11500 | F37: =D37*E37 | G37: 1725000 | J37: 2026-04-23 | K37: Kaji Yudi | L37: JSO-Fossil | M37: 150 | N37: 11500 | O37: =M37*N37 | P37: 1725000
A38: 2026-04-23 | B38: Kaji Yudi | C38: JSO-Coksu | D38: 160 | E38: 11500 | F38: =D38*E38 | G38: 1840000 | J38: 2026-04-23 | K38: Kaji Yudi | L38: JSO-Coksu | M38: 160 | N38: 11500 | O38: =M38*N38 | P38: 1840000
... A55: 2026-04-24 | B55: Kaji Yudi | C55: JSO-Hitam | D55: 160 | E55: 12000 | F55: =D55*E55 | G55: 1920000 | J55: 2026-04-24 | K55: Kaji Yudi | L55: JSO-Hitam | M55: 160 | N55: 12000 | O55: =M55*N55 | P55: 1920000
A56: 2026-04-24 | B56: Kak Yudi | C56: DG-Hitam | D56: 140 | E56: 9000 | F56: =D56*E56 | G56: 1260000 | J56: 46135 | K56: Kak Yudi | L56: DG-Hitam | M56: 140 | N56: 9000 | O56: =M56*N56 | P56: 1260000
A57: 2026-04-24 | B57: Kak Yudi | C57: DG-Beige-L | D57: 1 | E57: 10000 | F57: =D57*E57 | G57: 10000 | J57: 46135 | K57: Kak Yudi | L57: DG-Beige-L | M57: 1 | N57: 10000 | O57: =M57*N57 | P57: 10000
A58: 2026-04-24 | B58: Kak Yudi | C58: DG-Beige | D58: 10 | E58: 9000 | F58: =D58*E58 | G58: 90000 | J58: 46135 | K58: Kak Yudi | L58: DG-Beige | M58: 10 | N58: 9000 | O58: =M58*N58 | P58: 90000
A59: 2026-04-24 | B59: Kak Yudi | C59: SPORT-Navy-M | D59: 2 | E59: 7500 | F59: =D59*E59 | G59: 15000 | J59: 46135 | K59: Kak Yudi | L59: SPORT-Navy-M | M59: 2 | N59: 7500 | O59: =M59*N59 | P59: 15000
A60: 2026-04-24 | B60: Kak Yudi | C60: SPORT-Cokelat Tua-M | D60: 1 | E60: 7500 | F60: =D60*E60 | G60: 7500 | J60: 46135 | K60: Kak Yudi | L60: SPORT-Cokelat Tua-M | M60: 1 | N60: 7500 | O60: =M60*N60 | P60: 7500
...

Sheet SKU_Tunggal
A1: SKU | B1: Harga Satuan
A2: DG-3PCS
A3: DG-Almond
A4: DG-Almond-L
A5: DG-Army
A6: DG-Army-L
A7: DG-Bata
A8: DG-Bata-L
A9: DG-Beige
A10: DG-Beige-L
A11: DG-Burgundy
A12: DG-Burgundy-L
A13: DG-Caramel
... A592: SPORT-Wardah-S

Sheet SKU_Induk
A1: SKU | B1: Harga Satuan
A2: DG-3PCS
A3: DG-M | B3: 10000
A4: DG-L | B4: 11500
A5: JSO | B5: 13000
A6: H.PM-L
A7: H.PM-M
A8: HM
A9: KOREAN-L
A10: KOREAN-XL
A11: Labubu
A12: Marissa
A13: P-Polos | B13: 13000
A14: P.Oval
A15: P.Polos-Anak
A16: S3 | B16: 10000
A17: SA-L | B17: 8000
A18: SA-M
A19: SA-XL
A20: SPORT-S | B20: 5500
A21: SPORT-M | B21: 8000
A22: SPORT-L | B22: 10000
A23: Kertas Resi | B23: 33000
A24: Plastik Packing Hitam | B24: 15000

Sheet Riwayat_Pelunasan
A1: Source | B1: Tgl_Hutang | C1: Nama | D1: Nominal_Bayar | E1: Tgl_Bayar
A2: Barang_Terhutang | B2: 2026-04-19 | C2: Kak Hari | D2: 1782500 | E2: 46135
A3: Barang_Terhutang | B3: 2026-04-19 | C3: Kak Hari | D3: 2024000 | E3: 46135
A4: Barang_Terhutang | B4: 2026-04-19 | C4: Kak Hari | D4: 2081500 | E4: 46135
A5: Barang_Terhutang | B5: 2026-04-19 | C5: Kak Hari | D5: 2001000 | E5: 46135
A6: Barang_Terhutang | B6: 2026-04-19 | C6: Kak Hari | D6: 1932000 | E6: 46135
A7: Barang_Terhutang | B7: 2026-04-19 | C7: Kak Hari | D7: 3921500 | E7: 2026-04-23
A8: Barang_Terhutang | B8: 2026-04-19 | C8: Kak Hari | D8: 1962000 | E8: 46135
A9: Barang_Terhutang | B9: 2026-04-19 | C9: Kak Hari | D9: 3888000 | E9: 46135
A10: Barang_Terhutang | B10: Pelunasan 18 Transaksi Terpilih | C10: Kak Hari | D10: 26055000 | E10: 2026-04-25
A11: Modal_Hutang | B11: Pelunasan 1 Transaksi Terpilih | C11: Kak Boden | D11: 10000000 | E11: 2026-04-27
A12: Modal_Hutang | B12: 2026-04-14 | C12: Kak Yudi | D12: 36832320 | E12: 2026-04-14
A13: Modal_Hutang | B13: 2026-04-14 | C13: Kak Yudi | D13: 26024400 | E13: 2026-04-20
A14: Modal_Hutang | B14: 2026-04-14 | C14: Kak Yudi | D14: 27476400 | E14: 2026-04-20
A15: Modal_Hutang | B15: 2026-04-14 | C15: Kak Yudi | D15: 28779000 | E15: 46135
A16: Modal_Hutang | B16: Pelunasan 2 Transaksi Terpilih | C16: Kak Yudi | D16: 33632400 | E16: 2026-04-28
A17: Modal_Hutang | B17: Pelunasan 1 Transaksi Terpilih | C17: Salim Cap | D17: 2000000 | E17: 46134
A18: Modal_Hutang | B18: Pelunasan 1 Transaksi Terpilih | C18: Salim Cap | D18: 3375000 | E18: 2026-04-30
A19: Modal_Hutang | B19: Pelunasan 3 Transaksi Terpilih | C19: Kak Yudi | D19: 31879200 | E19: 2026-05-04
A20: Barang_Terhutang | B20: Pelunasan 30 Transaksi Terpilih | C20: Kak Yudi | D20: 8336500 | E20: 46135
A21: Barang_Terhutang | B21: Pelunasan 70 Transaksi Terpilih | C21: Kak Yudi | D21: 3634000 | E21: 2026-05-04
A22: Barang_Terhutang | B22: Pelunasan 27 Transaksi Terpilih | C22: Kak Yudi | D22: 540500 | E22: 2026-05-07
A23: Barang_Terhutang | B23: Pelunasan 11 Transaksi Terpilih | C23: Kak Hari | D23: 14448000 | E23: 2026-05-07
A24: Modal_Hutang | B24: Pelunasan 2 Transaksi Terpilih | C24: Kak Yudi | D24: 38198400 | E24: 2026-05-07
A25: Modal_Hutang | B25: Pelunasan 1 Transaksi Terpilih | C25: Kak Boden | D25: 10000000 | E25: 2026-05-08
A26: Barang_Terhutang | B26: Pelunasan 1 Transaksi Terpilih | C26: Kak Yudi | D26: 5000 | E26: 2026-05-11
A27: Modal_Hutang | B27: Pelunasan 2 Transaksi Terpilih | C27: Kak Yudi | D27: 33518400 | E27: 2026-05-11
